Workbook

Sheet TOPSIS
A1: Концепции проектов | B1: Короткое название | E1: Критерии
A2: 1. СтудАктив — учёт инвентаря и мероприятий | B2: СтудАктив | E2: Техническая реализуемость
A3: 2. Посещаемость — QR-отметка на парах | B3: Посещаемость | E3: Практическая ценность
A4: 3. Мой рейтинг — трекер оценок и прогноз стипендии | B4: Мой рейтинг | E4: Понятность требований
A5: 4. Аудитории — бронирование аудиторий и оборудования | B5: Аудитории | E5: Потенциал развития
A11: Этап 1 — экспертные оценки (трехточечные оценки)
A12: Эксперт 1 Шабунин | B12: Техническая реализуемость | E12: Практическая ценность | H12: Понятность требований | K12: Потенциал развития
B13: I (песс) | C13: m (ожид) | D13: u (оптимист) | E13: I (песс) | F13: m (ожид) | G13: u (оптимист) | H13: I (песс) | I13: m (ожид) | J13: u (оптимист) | K13: I (песс) | L13: m (ожид) | M13: u (оптимист)
A14: СтудАктив
A15: Посещаемость
A16: Мой рейтинг
A17: Аудитории
A18: Вес критерия
A19: Тип критерия | B19: max | E19: max | H19: max | K19: max
A24: Эксперт 2 Попов | B24: Техническая реализуемость | E24: Практическая ценность | H24: Понятность требований | K24: Потенциал развития
B25: I (песс) | C25: m (ожид) | D25: u (оптимист) | E25: I (песс) | F25: m (ожид) | G25: u (оптимист) | H25: I (песс) | I25: m (ожид) | J25: u (оптимист) | K25: I (песс) | L25: m (ожид) | M25: u (оптимист)
A26: СтудАктив
A27: Посещаемость
A28: Мой рейтинг
A29: Аудитории
A30: Вес критерия
A31: Тип критерия | B31: max | E31: max | H31: max | K31: max
A36: Эксперт 3 Карманова | B36: Техническая реализуемость | E36: Практическая ценность | H36: Понятность требований | K36: Потенциал развития
B37: I (песс) | C37: m (ожид) | D37: u (оптимист) | E37: I (песс) | F37: m (ожид) | G37: u (оптимист) | H37: I (песс) | I37: m (ожид) | J37: u (оптимист) | K37: I (песс) | L37: m (ожид) | M37: u (оптимист)
A38: СтудАктив
A39: Посещаемость
A40: Мой рейтинг
A41: Аудитории
A42: Вес критерия
A43: Тип критерия | B43: max | E43: max | H43: max | K43: max
A49: Этап 2 — агрегация и нормализация | B49: Техническая реализуемость | E49: Практическая ценность | H49: Понятность требований | K49: Потенциал развития
B50: I | C50: m | D50: u | E50: I | F50: m | G50: u | H50: I | I50: m | J50: u | K50: I | L50: m | M50: u
A51: СтудАктив | B51: =MIN(B14,B26,B38) -> 0 | C51: =AVERAGE(C14,C26,C38) -> #DIV/0! | D51: =MAX(D14,D26,D38) -> 0 | E51: =MIN(E14,E26,E38) -> 0 | F51: =MIN(F14,F26,F38) -> 0 | G51: =MIN(G14,G26,G38) -> 0 | H51: =MIN(H14,H26,H38) -> 0 | I51: =MIN(I14,I26,I38) -> 0 | J51: =MIN(J14,J26,J38) -> 0 | K51: =MIN(K14,K26,K38) -> 0 | L51: =MIN(L14,L26,L38) -> 0 | M51: =MIN(M14,M26,M38) -> 0
A52: Посещаемость | B52: =MIN(B15,B27,B39) -> 0 | C52: =AVERAGE(C15,C27,C39) -> #DIV/0! | D52: =MAX(D15,D27,D39) -> 0 | E52: =MIN(E15,E27,E39) -> 0 | F52: =MIN(F15,F27,F39) -> 0 | G52: =MIN(G15,G27,G39) -> 0 | H52: =MIN(H15,H27,H39) -> 0 | I52: =MIN(I15,I27,I39) -> 0 | J52: =MIN(J15,J27,J39) -> 0 | K52: =MIN(K15,K27,K39) -> 0 | L52: =MIN(L15,L27,L39) -> 0 | M52: =MIN(M15,M27,M39) -> 0
A53: Мой рейтинг | B53: =MIN(B16,B28,B40) -> 0 | C53: =AVERAGE(C16,C28,C40) -> #DIV/0! | D53: =MAX(D16,D28,D40) -> 0 | E53: =MIN(E16,E28,E40) -> 0 | F53: =MIN(F16,F28,F40) -> 0 | G53: =MIN(G16,G28,G40) -> 0 | H53: =MIN(H16,H28,H40) -> 0 | I53: =MIN(I16,I28,I40) -> 0 | J53: =MIN(J16,J28,J40) -> 0 | K53: =MIN(K16,K28,K40) -> 0 | L53: =MIN(L16,L28,L40) -> 0 | M53: =MIN(M16,M28,M40) -> 0
A54: Аудитории | B54: =MIN(B17,B29,B41) -> 0 | C54: =AVERAGE(C17,C29,C41) -> #DIV/0! | D54: =MAX(D17,D29,D41) -> 0 | E54: =MIN(E17,E29,E41) -> 0 | F54: =MIN(F17,F29,F41) -> 0 | G54: =MIN(G17,G29,G41) -> 0 | H54: =MIN(H17,H29,H41) -> 0 | I54: =MIN(I17,I29,I41) -> 0 | J54: =MIN(J17,J29,J41) -> 0 | K54: =MIN(K17,K29,K41) -> 0 | L54: =MIN(L17,L29,L41) -> 0 | M54: =MIN(M17,M29,M41) -> 0
B55: Техническая реализуемость | E55: Практическая ценность | H55: Понятность требований | K55: Потенциал развития
A56: Нормализация | B56: I | C56: m | D56: u | E56: I | F56: m | G56: u | H56: I | I56: m | J56: u | K56: I | L56: m | M56: u
A57: СтудАктив | B57: =B51/MAX($D$51:$D$54) -> #DIV/0! | C57: =C51/MAX($D$51:$D$54) -> #DIV/0! | D57: =D51/MAX($D$51:$D$54) -> #DIV/0! | E57: =E51/MAX($G$51:$G$54) -> #DIV/0! | F57: =F51/MAX($G$51:$G$54) -> #DIV/0! | G57: =G51/MAX($G$51:$G$54) -> #DIV/0! | H57: =H51/MAX($J$51:$J$54) -> #DIV/0! | I57: =I51/MAX($J$51:$J$54) -> #DIV/0! | J57: =J51/MAX($J$51:$J$54) -> #DIV/0! | K57: =K51/MAX($M$51:$M$54) -> #DIV/0! | L57: =L51/MAX($M$51:$M$54) -> #DIV/0! | M57: =M51/MAX($M$51:$M$54) -> #DIV/0!
A58: Посещаемость | B58: =B52/MAX($D$51:$D$54) -> #DIV/0! | C58: =C52/MAX($D$51:$D$54) -> #DIV/0! | D58: =D52/MAX($D$51:$D$54) -> #DIV/0! | E58: =E52/MAX($G$51:$G$54) -> #DIV/0! | F58: =F52/MAX($G$51:$G$54) -> #DIV/0! | G58: =G52/MAX($G$51:$G$54) -> #DIV/0! | H58: =H52/MAX($J$51:$J$54) -> #DIV/0! | I58: =I52/MAX($J$51:$J$54) -> #DIV/0! | J58: =J52/MAX($J$51:$J$54) -> #DIV/0! | K58: =K52/MAX($M$51:$M$54) -> #DIV/0! | L58: =L52/MAX($M$51:$M$54) -> #DIV/0! | M58: =M52/MAX($M$51:$M$54) -> #DIV/0!
...

Sheet МАИ Эксперт 1
A1: МАИ — метод анализа иерархий
A2: Матрицы построены из агрегированных ожидаемых оценок (m-компонент TFN с листа TOPSIS). При идеально согласованных данных CR = 0.
A4: 1. Матрица парных сравнений критериев
B5: С1 | C5: С2 | D5: С3 | E5: С4
A6: С1 | B6: 1 | C6: 0 | D6: 0 | E6: 0
A7: С2 | B7: =1/C6 -> #DIV/0! | C7: 1 | D7: 0 | E7: 0
A8: С3 | B8: =1/D6 -> #DIV/0! | C8: =1/D7 -> #DIV/0! | D8: 1 | E8: 0
A9: С4 | B9: =1/E6 -> #DIV/0! | C9: =1/E7 -> #DIV/0! | D9: =1/E8 -> #DIV/0! | E9: 1
A11: GM_i
A12: С1 | B12: =PRODUCT(B6:E6)^(1/4) -> 0
A13: С2 | B13: =PRODUCT(B7:E7)^(1/4) -> #DIV/0!
A14: С3 | B14: =PRODUCT(B8:E8)^(1/4) -> #DIV/0!
A15: С4 | B15: =PRODUCT(B9:E9)^(1/4) -> #DIV/0!
A16: Сумма GM | B16: =SUM(B12:B15) -> #DIV/0!
A18: Вектор приоритетов w
A19: С1 | B19: =B12/$B$16 -> #DIV/0!
A20: С2 | B20: =B13/$B$16 -> #DIV/0!
A21: С3 | B21: =B14/$B$16 -> #DIV/0!
A22: С4 | B22: =B15/$B$16 -> #DIV/0!
A24: Согласованность: Aw_i = Σ a_ij·w_j
A25: С1 | B25: =SUMPRODUCT(B6:E6,$B$19:$B$22) -> #DIV/0!
A26: С2 | B26: =SUMPRODUCT(B7:E7,$B$19:$B$22) -> #DIV/0!
A27: С3 | B27: =SUMPRODUCT(B8:E8,$B$19:$B$22) -> #DIV/0!
A28: С4 | B28: =SUMPRODUCT(B9:E9,$B$19:$B$22) -> #DIV/0!
A30: Aw_i / w_i
A31: С1 | B31: =B25/B19 -> #DIV/0!
A32: С2 | B32: =B26/B20 -> #DIV/0!
A33: С3 | B33: =B27/B21 -> #DIV/0!
A34: С4 | B34: =B28/B22 -> #DIV/0!
A36: λ_max | B36: =AVERAGE(B31:B34) -> #DIV/0!
A37: CI = (λ_max - n)/(n-1) | B37: =(B36-4)/(4-1) -> #DIV/0!
A38: RI | B38: 1.12
A39: CR = CI / RI | B39: =B37/B38 -> #DIV/0!
A40: Согласовано? (CR ≤ 0.1) | B40: =IF(B39<=0.1,"Да","Нет") -> #DIV/0!
A42: 2. Матрица альтернатив по критерию С1
B43: СтудАктив | C43: Посещаемость | D43: Мой рейтинг | E43: Аудитории
A44: СтудАктив | B44: 1 | C44: 0 | D44: 0 | E44: 0
A45: Посещаемость | B45: =1/C44 -> #DIV/0! | C45: 1 | D45: 0 | E45: 0
A46: Мой рейтинг | B46: =1/D44 -> #DIV/0! | C46: =1/D45 -> #DIV/0! | D46: 1 | E46: 0
A47: Аудитории | B47: =1/E44 -> #DIV/0! | C47: =1/E45 -> #DIV/0! | D47: =1/E46 -> #DIV/0! | E47: 1
...

Sheet МАИ (Эксперт 2)
A1: МАИ — метод анализа иерархий
A2: Матрицы построены из агрегированных ожидаемых оценок (m-компонент TFN с листа TOPSIS). При идеально согласованных данных CR = 0.
A4: 1. Матрица парных сравнений критериев
B5: С1 | C5: С2 | D5: С3 | E5: С4
A6: С1 | B6: 1 | C6: 0 | D6: 0 | E6: 0
A7: С2 | B7: =1/C6 -> #DIV/0! | C7: 1 | D7: 0 | E7: 0
A8: С3 | B8: =1/D6 -> #DIV/0! | C8: =1/D7 -> #DIV/0! | D8: 1 | E8: 0
A9: С4 | B9: =1/E6 -> #DIV/0! | C9: =1/E7 -> #DIV/0! | D9: =1/E8 -> #DIV/0! | E9: 1
A11: GM_i
A12: С1 | B12: =PRODUCT(B6:E6)^(1/4) -> 0
A13: С2 | B13: =PRODUCT(B7:E7)^(1/4) -> #DIV/0!
A14: С3 | B14: =PRODUCT(B8:E8)^(1/4) -> #DIV/0!
A15: С4 | B15: =PRODUCT(B9:E9)^(1/4) -> #DIV/0!
A16: Сумма GM | B16: =SUM(B12:B15) -> #DIV/0!
A18: Вектор приоритетов w
A19: С1 | B19: =B12/$B$16 -> #DIV/0!
A20: С2 | B20: =B13/$B$16 -> #DIV/0!
A21: С3 | B21: =B14/$B$16 -> #DIV/0!
A22: С4 | B22: =B15/$B$16 -> #DIV/0!
A24: Согласованность: Aw_i = Σ a_ij·w_j
A25: С1 | B25: =SUMPRODUCT(B6:E6,$B$19:$B$22) -> #DIV/0!
A26: С2 | B26: =SUMPRODUCT(B7:E7,$B$19:$B$22) -> #DIV/0!
A27: С3 | B27: =SUMPRODUCT(B8:E8,$B$19:$B$22) -> #DIV/0!
A28: С4 | B28: =SUMPRODUCT(B9:E9,$B$19:$B$22) -> #DIV/0!
A30: Aw_i / w_i
A31: С1 | B31: =B25/B19 -> #DIV/0!
A32: С2 | B32: =B26/B20 -> #DIV/0!
A33: С3 | B33: =B27/B21 -> #DIV/0!
A34: С4 | B34: =B28/B22 -> #DIV/0!
A36: λ_max | B36: =AVERAGE(B31:B34) -> #DIV/0!
A37: CI = (λ_max - n)/(n-1) | B37: =(B36-4)/(4-1) -> #DIV/0!
A38: RI | B38: 1.12
A39: CR = CI / RI | B39: =B37/B38 -> #DIV/0!
A40: Согласовано? (CR ≤ 0.1) | B40: =IF(B39<=0.1,"Да","Нет") -> #DIV/0!
A42: 2. Матрица альтернатив по критерию С1
B43: СтудАктив | C43: Посещаемость | D43: Мой рейтинг | E43: Аудитории
A44: СтудАктив | B44: 1 | C44: 0 | D44: 0 | E44: 0
A45: Посещаемость | B45: =1/C44 -> #DIV/0! | C45: 1 | D45: 0 | E45: 0
A46: Мой рейтинг | B46: =1/D44 -> #DIV/0! | C46: =1/D45 -> #DIV/0! | D46: 1 | E46: 0
A47: Аудитории | B47: =1/E44 -> #DIV/0! | C47: =1/E45 -> #DIV/0! | D47: =1/E46 -> #DIV/0! | E47: 1
...

Sheet МАИ (Эксперт 3)
A1: МАИ — метод анализа иерархий
A2: Матрицы построены из агрегированных ожидаемых оценок (m-компонент TFN с листа TOPSIS). При идеально согласованных данных CR = 0.
A4: 1. Матрица парных сравнений критериев
B5: С1 | C5: С2 | D5: С3 | E5: С4
A6: С1 | B6: 1 | C6: 0 | D6: 0 | E6: 0
A7: С2 | B7: =1/C6 -> #DIV/0! | C7: 1 | D7: 0 | E7: 0
A8: С3 | B8: =1/D6 -> #DIV/0! | C8: =1/D7 -> #DIV/0! | D8: 1 | E8: 0
A9: С4 | B9: =1/E6 -> #DIV/0! | C9: =1/E7 -> #DIV/0! | D9: =1/E8 -> #DIV/0! | E9: 1
A11: GM_i
A12: С1 | B12: =PRODUCT(B6:E6)^(1/4) -> 0
A13: С2 | B13: =PRODUCT(B7:E7)^(1/4) -> #DIV/0!
A14: С3 | B14: =PRODUCT(B8:E8)^(1/4) -> #DIV/0!
A15: С4 | B15: =PRODUCT(B9:E9)^(1/4) -> #DIV/0!
A16: Сумма GM | B16: =SUM(B12:B15) -> #DIV/0!
A18: Вектор приоритетов w
A19: С1 | B19: =B12/$B$16 -> #DIV/0!
A20: С2 | B20: =B13/$B$16 -> #DIV/0!
A21: С3 | B21: =B14/$B$16 -> #DIV/0!
A22: С4 | B22: =B15/$B$16 -> #DIV/0!
A24: Согласованность: Aw_i = Σ a_ij·w_j
A25: С1 | B25: =SUMPRODUCT(B6:E6,$B$19:$B$22) -> #DIV/0!
A26: С2 | B26: =SUMPRODUCT(B7:E7,$B$19:$B$22) -> #DIV/0!
A27: С3 | B27: =SUMPRODUCT(B8:E8,$B$19:$B$22) -> #DIV/0!
A28: С4 | B28: =SUMPRODUCT(B9:E9,$B$19:$B$22) -> #DIV/0!
A30: Aw_i / w_i
A31: С1 | B31: =B25/B19 -> #DIV/0!
A32: С2 | B32: =B26/B20 -> #DIV/0!
A33: С3 | B33: =B27/B21 -> #DIV/0!
A34: С4 | B34: =B28/B22 -> #DIV/0!
A36: λ_max | B36: =AVERAGE(B31:B34) -> #DIV/0!
A37: CI = (λ_max - n)/(n-1) | B37: =(B36-4)/(4-1) -> #DIV/0!
A38: RI | B38: 1.12
A39: CR = CI / RI | B39: =B37/B38 -> #DIV/0!
A40: Согласовано? (CR ≤ 0.1) | B40: =IF(B39<=0.1,"Да","Нет") -> #DIV/0!
A42: 2. Матрица альтернатив по критерию С1
B43: СтудАктив | C43: Посещаемость | D43: Мой рейтинг | E43: Аудитории
A44: СтудАктив | B44: 1 | C44: 0 | D44: 0 | E44: 0
A45: Посещаемость | B45: =1/C44 -> #DIV/0! | C45: 1 | D45: 0 | E45: 0
A46: Мой рейтинг | B46: =1/D44 -> #DIV/0! | C46: =1/D45 -> #DIV/0! | D46: 1 | E46: 0
A47: Аудитории | B47: =1/E44 -> #DIV/0! | C47: =1/E45 -> #DIV/0! | D47: =1/E46 -> #DIV/0! | E47: 1
...

Sheet МАИ Итоги
A1: МАИ — метод анализа иерархий
A2: Матрицы построены из агрегированных ожидаемых оценок (m-компонент TFN с листа TOPSIS). При идеально согласованных данных CR = 0.
A4: 1. Матрица парных сравнений критериев
B5: С1 | C5: С2 | D5: С3 | E5: С4
A6: С1 | B6: 1 | C6: =('МАИ Эксперт 1'!C6 * 'МАИ (Эксперт 2)'!C6 * 'МАИ (Эксперт 3)'!C6)^(1/3) -> 0 | D6: =('МАИ Эксперт 1'!D6 * 'МАИ (Эксперт 2)'!D6 * 'МАИ (Эксперт 3)'!D6)^(1/3) -> 0 | E6: =('МАИ Эксперт 1'!E6 * 'МАИ (Эксперт 2)'!E6 * 'МАИ (Эксперт 3)'!E6)^(1/3) -> 0
A7: С2 | B7: =1/C6 -> #DIV/0! | C7: 1 | D7: =('МАИ Эксперт 1'!D7 * 'МАИ (Эксперт 2)'!D7 * 'МАИ (Эксперт 3)'!D7)^(1/3) -> 0 | E7: =('МАИ Эксперт 1'!E7 * 'МАИ (Эксперт 2)'!E7 * 'МАИ (Эксперт 3)'!E7)^(1/3) -> 0
A8: С3 | B8: =1/D6 -> #DIV/0! | C8: =1/D7 -> #DIV/0! | D8: 1 | E8: =('МАИ Эксперт 1'!E8 * 'МАИ (Эксперт 2)'!E8 * 'МАИ (Эксперт 3)'!E8)^(1/3) -> 0
A9: С4 | B9: =1/E6 -> #DIV/0! | C9: =1/E7 -> #DIV/0! | D9: =1/E8 -> #DIV/0! | E9: 1
A11: GM_i
A12: С1 | B12: =PRODUCT(B6:E6)^(1/4) -> 0
A13: С2 | B13: =PRODUCT(B7:E7)^(1/4) -> #DIV/0!
A14: С3 | B14: =PRODUCT(B8:E8)^(1/4) -> #DIV/0!
A15: С4 | B15: =PRODUCT(B9:E9)^(1/4) -> #DIV/0!
A16: Сумма GM | B16: =SUM(B12:B15) -> #DIV/0!
A18: Вектор приоритетов w
A19: С1 | B19: =B12/$B$16 -> #DIV/0!
A20: С2 | B20: =B13/$B$16 -> #DIV/0!
A21: С3 | B21: =B14/$B$16 -> #DIV/0!
A22: С4 | B22: =B15/$B$16 -> #DIV/0!
A24: Согласованность: Aw_i = Σ a_ij·w_j
A25: С1 | B25: =SUMPRODUCT(B6:E6,$B$19:$B$22) -> #DIV/0!
A26: С2 | B26: =SUMPRODUCT(B7:E7,$B$19:$B$22) -> #DIV/0!
A27: С3 | B27: =SUMPRODUCT(B8:E8,$B$19:$B$22) -> #DIV/0!
A28: С4 | B28: =SUMPRODUCT(B9:E9,$B$19:$B$22) -> #DIV/0!
A30: Aw_i / w_i
A31: С1 | B31: =B25/B19 -> #DIV/0!
A32: С2 | B32: =B26/B20 -> #DIV/0!
A33: С3 | B33: =B27/B21 -> #DIV/0!
A34: С4 | B34: =B28/B22 -> #DIV/0!
A36: λ_max | B36: =AVERAGE(B31:B34) -> #DIV/0!
A37: CI = (λ_max - n)/(n-1) | B37: =(B36-4)/(4-1) -> #DIV/0!
A38: RI | B38: 1.12
A39: CR = CI / RI | B39: =B37/B38 -> #DIV/0!
A40: Согласовано? (CR ≤ 0.1) | B40: =IF(B39<=0.1,"Да","Нет") -> #DIV/0!
A42: 2. Матрица альтернатив по критерию С1
B43: СтудАктив | C43: Посещаемость | D43: Мой рейтинг | E43: Аудитории
A44: СтудАктив | B44: 1 | C44: =('МАИ Эксперт 1'!C44 * 'МАИ (Эксперт 2)'!C44 * 'МАИ (Эксперт 3)'!C44)^(1/3) -> 0 | D44: =('МАИ Эксперт 1'!D44 * 'МАИ (Эксперт 2)'!D44 * 'МАИ (Эксперт 3)'!D44)^(1/3) -> 0 | E44: =('МАИ Эксперт 1'!E44 * 'МАИ (Эксперт 2)'!E44 * 'МАИ (Эксперт 3)'!E44)^(1/3) -> 0
A45: Посещаемость | B45: =1/C44 -> #DIV/0! | C45: 1 | D45: =('МАИ Эксперт 1'!D45 * 'МАИ (Эксперт 2)'!D45 * 'МАИ (Эксперт 3)'!D45)^(1/3) -> 0 | E45: =('МАИ Эксперт 1'!E45 * 'МАИ (Эксперт 2)'!E45 * 'МАИ (Эксперт 3)'!E45)^(1/3) -> 0
A46: Мой рейтинг | B46: =1/D44 -> #DIV/0! | C46: =1/D45 -> #DIV/0! | D46: 1 | E46: =('МАИ Эксперт 1'!E46 * 'МАИ (Эксперт 2)'!E46 * 'МАИ (Эксперт 3)'!E46)^(1/3) -> 0
A47: Аудитории | B47: =1/E44 -> #DIV/0! | C47: =1/E45 -> #DIV/0! | D47: =1/E46 -> #DIV/0! | E47: 1
...

Sheet Итог
A1: Сводная таблица: TOPSIS vs МАИ
A2: TOPSIS: чем больше CC, тем лучше. МАИ: чем больше S, тем лучше.
A4: Альтернатива | B4: CC (TOPSIS) | C4: Ранг TOPSIS | D4: S (МАИ) | E4: Ранг МАИ | F4: Совпадение
A5: СтудАктив | B5: =TOPSIS!B88 -> #DIV/0! | C5: =TOPSIS!C88 -> #DIV/0! | D5: ='МАИ Эксперт 1'!F197 -> #DIV/0! | E5: ='МАИ Эксперт 1'!G197 -> #DIV/0! | F5: =IF(C5=E5,"Да","Нет") -> #DIV/0!
A6: Посещаемость | B6: =TOPSIS!B89 -> #DIV/0! | C6: =TOPSIS!C89 -> #DIV/0! | D6: ='МАИ Эксперт 1'!F198 -> #DIV/0! | E6: ='МАИ Эксперт 1'!G198 -> #DIV/0! | F6: =IF(C6=E6,"Да","Нет") -> #DIV/0!
A7: Мой рейтинг | B7: =TOPSIS!B90 -> #DIV/0! | C7: =TOPSIS!C90 -> #DIV/0! | D7: ='МАИ Эксперт 1'!F199 -> #DIV/0! | E7: ='МАИ Эксперт 1'!G199 -> #DIV/0! | F7: =IF(C7=E7,"Да","Нет") -> #DIV/0!
A8: Аудитории | B8: =TOPSIS!B91 -> #DIV/0! | C8: =TOPSIS!C91 -> #DIV/0! | D8: ='МАИ Эксперт 1'!F200 -> #DIV/0! | E8: ='МАИ Эксперт 1'!G200 -> #DIV/0! | F8: =IF(C8=E8,"Да","Нет") -> #DIV/0!
A11: Коэффициент ранговой корреляции Спирмена | D11: =1-6*((C5-E5)^2+(C6-E6)^2+(C7-E7)^2+(C8-E8)^2)/(4*(4^2-1)) -> #DIV/0! | E11: ρ
A13: Победитель по TOPSIS | D13: {=INDEX(A5:A8,MATCH(MAX(B5:B8),B5:B8,0))} -> #DIV/0!
A14: Победитель по МАИ | D14: {=INDEX(A5:A8,MATCH(MAX(D5:D8),D5:D8,0))} -> #DIV/0!
